<mujoco model="ur10e">
  <body name="base_link" pos="0 0 0">
    <inertial mass="4.0" pos="0 0 0" diaginertia="0.0061063308908 0.0061063308908 0.01125"/>
    <geom type="mesh" contype="0" conaffinity="0" rgba="0.7 0.7 0.7 1" mesh="base"/>
    <body name="shoulder_link" pos="0 0 0.181">
      <inertial pos="0 0 0" mass="7.778" diaginertia="0.0315 0.0315 0.02188"/>
      <joint name="shoulder_pan_joint" pos="0 0 0" axis="0 0 1"/>
      <geom type="mesh" contype="2" conaffinity="1" group="1" density="0" rgba="0.7 0.7 0.7 1" mesh="shoulder"/>
      <geom type="mesh" contype="0" conaffinity="0" rgba="0.7 0.7 0.7 1" mesh="shoulder"/>
      <body name="upper_arm_link" pos="0 0.176 0" quat="0.707105 0 0.707108 0">
        <inertial pos="0 0 0.3065" mass="12.93" diaginertia="0.42307 0.42307 0.0364"/>
        <joint name="shoulder_lift_joint" pos="0 0 0" axis="0 1 0"/>
        <geom type="mesh" contype="2" conaffinity="1" group="1" density="0" rgba="0.7 0.7 0.7 1" mesh="upperarm"/>
        <geom type="mesh" contype="0" conaffinity="0" rgba="0.7 0.7 0.7 1" mesh="upperarm"/>
        <body name="forearm_link" pos="0 -0.137 0.613">
          <inertial pos="0 0 0.2855" mass="3.87" diaginertia="0.11059 0.11059 0.01088"/>
          <joint name="elbow_joint" pos="0 0 0" axis="0 1 0"/>
          <geom type="mesh" contype="2" conaffinity="1" group="1" density="0" rgba="0.7 0.7 0.7 1" mesh="forearm"/>
          <geom type="mesh" contype="0" conaffinity="0" rgba="0.7 0.7 0.7 1" mesh="forearm"/>
          <body name="wrist_1_link" pos="0 0 0.571" quat="0.707105 0 0.707108 0">
            <inertial pos="0 0.135 0" quat="0.5 0.5 -0.5 0.5" mass="1.96" diaginertia="0.005108 0.005108 0.0055125"/>
            <joint name="wrist_1_joint" pos="0 0 0" axis="0 1 0"/>
            <geom type="mesh" contype="2" conaffinity="1" group="1" density="0" rgba="0.7 0.7 0.7 1" mesh="wrist1"/>
            <geom type="mesh" contype="0" conaffinity="0" rgba="0.7 0.7 0.7 1" mesh="wrist1"/>
            <body name="wrist_2_link" pos="0 0.135 0">
              <inertial pos="0 0 0.12" quat="0.5 0.5 -0.5 0.5" mass="1.96" diaginertia="0.005108 0.005108 0.0055125"/>
              <joint name="wrist_2_joint" pos="0 0 0" axis="0 0 1"/>
              <geom type="mesh" contype="2" conaffinity="1" group="1" density="0" rgba="0.7 0.7 0.7 1" mesh="wrist2"/>
              <geom type="mesh" contype="0" conaffinity="0" rgba="0.7 0.7 0.7 1" mesh="wrist2"/>
              <body name="wrist_3_link" pos="0 0 0.12">
                <inertial pos="0 0.092 0" quat="0.5 0.5 -0.5 0.5" mass="0.202" diaginertia="0.000205 0.000144 0.000144"/>
                <joint name="wrist_3_joint" pos="0 0 0" axis="0 1 0"/>
                <geom type="mesh" contype="2" conaffinity="1" group="1" density="0" rgba="0.7 0.7 0.7 1" mesh="wrist3"/>
                <geom type="mesh" contype="0" conaffinity="0" rgba="0.7 0.7 0.7 1" mesh="wrist3"/>
                <body name="ee_stick" pos="0 0.092 0" euler="-1.57 0 0">
                  <geom name="ee_stick_geom" type="cylinder" contype="2" conaffinity="1" size="0.005 0.088 " density ='0' rgba="0.3 0.3 0.9 1"/>
                  <site name="end_effector" pos="0 0 0.088" size="0.01" rgba="0 1 0 1"/>
                </body>
              </body>
            </body>
          </body>
        </body>
      </body>
    </body>
  </body>
</mujoco>
